Traceback (most recent call last):
  File "/usr/local/lib/python3.9/site-packages/jupyter_cache/executors/utils.py", line 51, in single_nb_execution
    executenb(
  File "/usr/local/lib/python3.9/site-packages/nbclient/client.py", line 1112, in execute
    return NotebookClient(nb=nb, resources=resources, km=km, **kwargs).execute()
  File "/usr/local/lib/python3.9/site-packages/nbclient/util.py", line 74, in wrapped
    return just_run(coro(*args, **kwargs))
  File "/usr/local/lib/python3.9/site-packages/nbclient/util.py", line 53, in just_run
    return loop.run_until_complete(coro)
  File "/usr/local/Cellar/python@3.9/3.9.7/Frameworks/Python.framework/Versions/3.9/lib/python3.9/asyncio/base_events.py", line 642, in run_until_complete
    return future.result()
  File "/usr/local/lib/python3.9/site-packages/nbclient/client.py", line 553, in async_execute
    await self.async_execute_cell(
  File "/usr/local/lib/python3.9/site-packages/nbclient/client.py", line 857, in async_execute_cell
    self._check_raise_for_error(cell, exec_reply)
  File "/usr/local/lib/python3.9/site-packages/nbclient/client.py", line 760, in _check_raise_for_error
    raise CellExecutionError.from_cell_and_msg(cell, exec_reply_content)
nbclient.exceptions.CellExecutionError: An error occurred while executing the following cell:
------------------
respuesta = requests.get('http://localhost:3000/')
pagina = BeautifulSoup(respuesta.text, 'html.parser')
peliculas = obtener_peliculas_comom_componente(pagina)
peliculas_lista_de_diccionarios = obtener_peliculas_como_lista_diccionario(peliculas)
guardar_como_csv(peliculas_lista_de_diccionarios)
------------------

[0;31m---------------------------------------------------------------------------[0m
[0;31mConnectionRefusedError[0m                    Traceback (most recent call last)
[0;32m/usr/local/lib/python3.9/site-packages/urllib3/connection.py[0m in [0;36m_new_conn[0;34m(self)[0m
[1;32m    168[0m         [0;32mtry[0m[0;34m:[0m[0;34m[0m[0;34m[0m[0m
[0;32m--> 169[0;31m             conn = connection.create_connection(
[0m[1;32m    170[0m                 [0;34m([0m[0mself[0m[0;34m.[0m[0m_dns_host[0m[0;34m,[0m [0mself[0m[0;34m.[0m[0mport[0m[0;34m)[0m[0;34m,[0m [0mself[0m[0;34m.[0m[0mtimeout[0m[0;34m,[0m [0;34m**[0m[0mextra_kw[0m[0;34m[0m[0;34m[0m[0m

[0;32m/usr/local/lib/python3.9/site-packages/urllib3/util/connection.py[0m in [0;36mcreate_connection[0;34m(address, timeout, source_address, socket_options)[0m
[1;32m     95[0m     [0;32mif[0m [0merr[0m [0;32mis[0m [0;32mnot[0m [0;32mNone[0m[0;34m:[0m[0;34m[0m[0;34m[0m[0m
[0;32m---> 96[0;31m         [0;32mraise[0m [0merr[0m[0;34m[0m[0;34m[0m[0m
[0m[1;32m     97[0m [0;34m[0m[0m

[0;32m/usr/local/lib/python3.9/site-packages/urllib3/util/connection.py[0m in [0;36mcreate_connection[0;34m(address, timeout, source_address, socket_options)[0m
[1;32m     85[0m                 [0msock[0m[0;34m.[0m[0mbind[0m[0;34m([0m[0msource_address[0m[0;34m)[0m[0;34m[0m[0;34m[0m[0m
[0;32m---> 86[0;31m             [0msock[0m[0;34m.[0m[0mconnect[0m[0;34m([0m[0msa[0m[0;34m)[0m[0;34m[0m[0;34m[0m[0m
[0m[1;32m     87[0m             [0;32mreturn[0m [0msock[0m[0;34m[0m[0;34m[0m[0m

[0;31mConnectionRefusedError[0m: [Errno 61] Connection refused

During handling of the above exception, another exception occurred:

[0;31mNewConnectionError[0m                        Traceback (most recent call last)
[0;32m/usr/local/lib/python3.9/site-packages/urllib3/connectionpool.py[0m in [0;36murlopen[0;34m(self, method, url, body, headers, retries, redirect, assert_same_host, timeout, pool_timeout, release_conn, chunked, body_pos, **response_kw)[0m
[1;32m    698[0m             [0;31m# Make the request on the httplib connection object.[0m[0;34m[0m[0;34m[0m[0m
[0;32m--> 699[0;31m             httplib_response = self._make_request(
[0m[1;32m    700[0m                 [0mconn[0m[0;34m,[0m[0;34m[0m[0;34m[0m[0m

[0;32m/usr/local/lib/python3.9/site-packages/urllib3/connectionpool.py[0m in [0;36m_make_request[0;34m(self, conn, method, url, timeout, chunked, **httplib_request_kw)[0m
[1;32m    393[0m             [0;32melse[0m[0;34m:[0m[0;34m[0m[0;34m[0m[0m
[0;32m--> 394[0;31m                 [0mconn[0m[0;34m.[0m[0mrequest[0m[0;34m([0m[0mmethod[0m[0;34m,[0m [0murl[0m[0;34m,[0m [0;34m**[0m[0mhttplib_request_kw[0m[0;34m)[0m[0;34m[0m[0;34m[0m[0m
[0m[1;32m    395[0m [0;34m[0m[0m

[0;32m/usr/local/lib/python3.9/site-packages/urllib3/connection.py[0m in [0;36mrequest[0;34m(self, method, url, body, headers)[0m
[1;32m    233[0m             [0mheaders[0m[0;34m[[0m[0;34m"User-Agent"[0m[0;34m][0m [0;34m=[0m [0m_get_default_user_agent[0m[0;34m([0m[0;34m)[0m[0;34m[0m[0;34m[0m[0m
[0;32m--> 234[0;31m         [0msuper[0m[0;34m([0m[0mHTTPConnection[0m[0;34m,[0m [0mself[0m[0;34m)[0m[0;34m.[0m[0mrequest[0m[0;34m([0m[0mmethod[0m[0;34m,[0m [0murl[0m[0;34m,[0m [0mbody[0m[0;34m=[0m[0mbody[0m[0;34m,[0m [0mheaders[0m[0;34m=[0m[0mheaders[0m[0;34m)[0m[0;34m[0m[0;34m[0m[0m
[0m[1;32m    235[0m [0;34m[0m[0m

[0;32m/usr/local/Cellar/python@3.9/3.9.7/Frameworks/Python.framework/Versions/3.9/lib/python3.9/http/client.py[0m in [0;36mrequest[0;34m(self, method, url, body, headers, encode_chunked)[0m
[1;32m   1278[0m         [0;34m"""Send a complete request to the server."""[0m[0;34m[0m[0;34m[0m[0m
[0;32m-> 1279[0;31m         [0mself[0m[0;34m.[0m[0m_send_request[0m[0;34m([0m[0mmethod[0m[0;34m,[0m [0murl[0m[0;34m,[0m [0mbody[0m[0;34m,[0m [0mheaders[0m[0;34m,[0m [0mencode_chunked[0m[0;34m)[0m[0;34m[0m[0;34m[0m[0m
[0m[1;32m   1280[0m [0;34m[0m[0m

[0;32m/usr/local/Cellar/python@3.9/3.9.7/Frameworks/Python.framework/Versions/3.9/lib/python3.9/http/client.py[0m in [0;36m_send_request[0;34m(self, method, url, body, headers, encode_chunked)[0m
[1;32m   1324[0m             [0mbody[0m [0;34m=[0m [0m_encode[0m[0;34m([0m[0mbody[0m[0;34m,[0m [0;34m'body'[0m[0;34m)[0m[0;34m[0m[0;34m[0m[0m
[0;32m-> 1325[0;31m         [0mself[0m[0;34m.[0m[0mendheaders[0m[0;34m([0m[0mbody[0m[0;34m,[0m [0mencode_chunked[0m[0;34m=[0m[0mencode_chunked[0m[0;34m)[0m[0;34m[0m[0;34m[0m[0m
[0m[1;32m   1326[0m [0;34m[0m[0m

[0;32m/usr/local/Cellar/python@3.9/3.9.7/Frameworks/Python.framework/Versions/3.9/lib/python3.9/http/client.py[0m in [0;36mendheaders[0;34m(self, message_body, encode_chunked)[0m
[1;32m   1273[0m             [0;32mraise[0m [0mCannotSendHeader[0m[0;34m([0m[0;34m)[0m[0;34m[0m[0;34m[0m[0m
[0;32m-> 1274[0;31m         [0mself[0m[0;34m.[0m[0m_send_output[0m[0;34m([0m[0mmessage_body[0m[0;34m,[0m [0mencode_chunked[0m[0;34m=[0m[0mencode_chunked[0m[0;34m)[0m[0;34m[0m[0;34m[0m[0m
[0m[1;32m   1275[0m [0;34m[0m[0m

[0;32m/usr/local/Cellar/python@3.9/3.9.7/Frameworks/Python.framework/Versions/3.9/lib/python3.9/http/client.py[0m in [0;36m_send_output[0;34m(self, message_body, encode_chunked)[0m
[1;32m   1033[0m         [0;32mdel[0m [0mself[0m[0;34m.[0m[0m_buffer[0m[0;34m[[0m[0;34m:[0m[0;34m][0m[0;34m[0m[0;34m[0m[0m
[0;32m-> 1034[0;31m         [0mself[0m[0;34m.[0m[0msend[0m[0;34m([0m[0mmsg[0m[0;34m)[0m[0;34m[0m[0;34m[0m[0m
[0m[1;32m   1035[0m [0;34m[0m[0m

[0;32m/usr/local/Cellar/python@3.9/3.9.7/Frameworks/Python.framework/Versions/3.9/lib/python3.9/http/client.py[0m in [0;36msend[0;34m(self, data)[0m
[1;32m    973[0m             [0;32mif[0m [0mself[0m[0;34m.[0m[0mauto_open[0m[0;34m:[0m[0;34m[0m[0;34m[0m[0m
[0;32m--> 974[0;31m                 [0mself[0m[0;34m.[0m[0mconnect[0m[0;34m([0m[0;34m)[0m[0;34m[0m[0;34m[0m[0m
[0m[1;32m    975[0m             [0;32melse[0m[0;34m:[0m[0;34m[0m[0;34m[0m[0m

[0;32m/usr/local/lib/python3.9/site-packages/urllib3/connection.py[0m in [0;36mconnect[0;34m(self)[0m
[1;32m    199[0m     [0;32mdef[0m [0mconnect[0m[0;34m([0m[0mself[0m[0;34m)[0m[0;34m:[0m[0;34m[0m[0;34m[0m[0m
[0;32m--> 200[0;31m         [0mconn[0m [0;34m=[0m [0mself[0m[0;34m.[0m[0m_new_conn[0m[0;34m([0m[0;34m)[0m[0;34m[0m[0;34m[0m[0m
[0m[1;32m    201[0m         [0mself[0m[0;34m.[0m[0m_prepare_conn[0m[0;34m([0m[0mconn[0m[0;34m)[0m[0;34m[0m[0;34m[0m[0m

[0;32m/usr/local/lib/python3.9/site-packages/urllib3/connection.py[0m in [0;36m_new_conn[0;34m(self)[0m
[1;32m    180[0m         [0;32mexcept[0m [0mSocketError[0m [0;32mas[0m [0me[0m[0;34m:[0m[0;34m[0m[0;34m[0m[0m
[0;32m--> 181[0;31m             raise NewConnectionError(
[0m[1;32m    182[0m                 [0mself[0m[0;34m,[0m [0;34m"Failed to establish a new connection: %s"[0m [0;34m%[0m [0me[0m[0;34m[0m[0;34m[0m[0m

[0;31mNewConnectionError[0m: <urllib3.connection.HTTPConnection object at 0x12438b070>: Failed to establish a new connection: [Errno 61] Connection refused

During handling of the above exception, another exception occurred:

[0;31mMaxRetryError[0m                             Traceback (most recent call last)
[0;32m/usr/local/lib/python3.9/site-packages/requests/adapters.py[0m in [0;36msend[0;34m(self, request, stream, timeout, verify, cert, proxies)[0m
[1;32m    438[0m             [0;32mif[0m [0;32mnot[0m [0mchunked[0m[0;34m:[0m[0;34m[0m[0;34m[0m[0m
[0;32m--> 439[0;31m                 resp = conn.urlopen(
[0m[1;32m    440[0m                     [0mmethod[0m[0;34m=[0m[0mrequest[0m[0;34m.[0m[0mmethod[0m[0;34m,[0m[0;34m[0m[0;34m[0m[0m

[0;32m/usr/local/lib/python3.9/site-packages/urllib3/connectionpool.py[0m in [0;36murlopen[0;34m(self, method, url, body, headers, retries, redirect, assert_same_host, timeout, pool_timeout, release_conn, chunked, body_pos, **response_kw)[0m
[1;32m    754[0m [0;34m[0m[0m
[0;32m--> 755[0;31m             retries = retries.increment(
[0m[1;32m    756[0m                 [0mmethod[0m[0;34m,[0m [0murl[0m[0;34m,[0m [0merror[0m[0;34m=[0m[0me[0m[0;34m,[0m [0m_pool[0m[0;34m=[0m[0mself[0m[0;34m,[0m [0m_stacktrace[0m[0;34m=[0m[0msys[0m[0;34m.[0m[0mexc_info[0m[0;34m([0m[0;34m)[0m[0;34m[[0m[0;36m2[0m[0;34m][0m[0;34m[0m[0;34m[0m[0m

[0;32m/usr/local/lib/python3.9/site-packages/urllib3/util/retry.py[0m in [0;36mincrement[0;34m(self, method, url, response, error, _pool, _stacktrace)[0m
[1;32m    573[0m         [0;32mif[0m [0mnew_retry[0m[0;34m.[0m[0mis_exhausted[0m[0;34m([0m[0;34m)[0m[0;34m:[0m[0;34m[0m[0;34m[0m[0m
[0;32m--> 574[0;31m             [0;32mraise[0m [0mMaxRetryError[0m[0;34m([0m[0m_pool[0m[0;34m,[0m [0murl[0m[0;34m,[0m [0merror[0m [0;32mor[0m [0mResponseError[0m[0;34m([0m[0mcause[0m[0;34m)[0m[0;34m)[0m[0;34m[0m[0;34m[0m[0m
[0m[1;32m    575[0m [0;34m[0m[0m

[0;31mMaxRetryError[0m: HTTPConnectionPool(host='localhost', port=3000): Max retries exceeded with url: / (Caused by NewConnectionError('<urllib3.connection.HTTPConnection object at 0x12438b070>: Failed to establish a new connection: [Errno 61] Connection refused'))

During handling of the above exception, another exception occurred:

[0;31mConnectionError[0m                           Traceback (most recent call last)
[0;32m/var/folders/qh/pvjjyjr96l329fgsgrwn11nr0000gp/T/ipykernel_18674/248040560.py[0m in [0;36m<module>[0;34m[0m
[0;32m----> 1[0;31m [0mrespuesta[0m [0;34m=[0m [0mrequests[0m[0;34m.[0m[0mget[0m[0;34m([0m[0;34m'http://localhost:3000/'[0m[0;34m)[0m[0;34m[0m[0;34m[0m[0m
[0m[1;32m      2[0m [0mpagina[0m [0;34m=[0m [0mBeautifulSoup[0m[0;34m([0m[0mrespuesta[0m[0;34m.[0m[0mtext[0m[0;34m,[0m [0;34m'html.parser'[0m[0;34m)[0m[0;34m[0m[0;34m[0m[0m
[1;32m      3[0m [0mpeliculas[0m [0;34m=[0m [0mobtener_peliculas_comom_componente[0m[0;34m([0m[0mpagina[0m[0;34m)[0m[0;34m[0m[0;34m[0m[0m
[1;32m      4[0m [0mpeliculas_lista_de_diccionarios[0m [0;34m=[0m [0mobtener_peliculas_como_lista_diccionario[0m[0;34m([0m[0mpeliculas[0m[0;34m)[0m[0;34m[0m[0;34m[0m[0m
[1;32m      5[0m [0mguardar_como_csv[0m[0;34m([0m[0mpeliculas_lista_de_diccionarios[0m[0;34m)[0m[0;34m[0m[0;34m[0m[0m

[0;32m/usr/local/lib/python3.9/site-packages/requests/api.py[0m in [0;36mget[0;34m(url, params, **kwargs)[0m
[1;32m     74[0m [0;34m[0m[0m
[1;32m     75[0m     [0mkwargs[0m[0;34m.[0m[0msetdefault[0m[0;34m([0m[0;34m'allow_redirects'[0m[0;34m,[0m [0;32mTrue[0m[0;34m)[0m[0;34m[0m[0;34m[0m[0m
[0;32m---> 76[0;31m     [0;32mreturn[0m [0mrequest[0m[0;34m([0m[0;34m'get'[0m[0;34m,[0m [0murl[0m[0;34m,[0m [0mparams[0m[0;34m=[0m[0mparams[0m[0;34m,[0m [0;34m**[0m[0mkwargs[0m[0;34m)[0m[0;34m[0m[0;34m[0m[0m
[0m[1;32m     77[0m [0;34m[0m[0m
[1;32m     78[0m [0;34m[0m[0m

[0;32m/usr/local/lib/python3.9/site-packages/requests/api.py[0m in [0;36mrequest[0;34m(method, url, **kwargs)[0m
[1;32m     59[0m     [0;31m# cases, and look like a memory leak in others.[0m[0;34m[0m[0;34m[0m[0m
[1;32m     60[0m     [0;32mwith[0m [0msessions[0m[0;34m.[0m[0mSession[0m[0;34m([0m[0;34m)[0m [0;32mas[0m [0msession[0m[0;34m:[0m[0;34m[0m[0;34m[0m[0m
[0;32m---> 61[0;31m         [0;32mreturn[0m [0msession[0m[0;34m.[0m[0mrequest[0m[0;34m([0m[0mmethod[0m[0;34m=[0m[0mmethod[0m[0;34m,[0m [0murl[0m[0;34m=[0m[0murl[0m[0;34m,[0m [0;34m**[0m[0mkwargs[0m[0;34m)[0m[0;34m[0m[0;34m[0m[0m
[0m[1;32m     62[0m [0;34m[0m[0m
[1;32m     63[0m [0;34m[0m[0m

[0;32m/usr/local/lib/python3.9/site-packages/requests/sessions.py[0m in [0;36mrequest[0;34m(self, method, url, params, data, headers, cookies, files, auth, timeout, allow_redirects, proxies, hooks, stream, verify, cert, json)[0m
[1;32m    540[0m         }
[1;32m    541[0m         [0msend_kwargs[0m[0;34m.[0m[0mupdate[0m[0;34m([0m[0msettings[0m[0;34m)[0m[0;34m[0m[0;34m[0m[0m
[0;32m--> 542[0;31m         [0mresp[0m [0;34m=[0m [0mself[0m[0;34m.[0m[0msend[0m[0;34m([0m[0mprep[0m[0;34m,[0m [0;34m**[0m[0msend_kwargs[0m[0;34m)[0m[0;34m[0m[0;34m[0m[0m
[0m[1;32m    543[0m [0;34m[0m[0m
[1;32m    544[0m         [0;32mreturn[0m [0mresp[0m[0;34m[0m[0;34m[0m[0m

[0;32m/usr/local/lib/python3.9/site-packages/requests/sessions.py[0m in [0;36msend[0;34m(self, request, **kwargs)[0m
[1;32m    653[0m [0;34m[0m[0m
[1;32m    654[0m         [0;31m# Send the request[0m[0;34m[0m[0;34m[0m[0m
[0;32m--> 655[0;31m         [0mr[0m [0;34m=[0m [0madapter[0m[0;34m.[0m[0msend[0m[0;34m([0m[0mrequest[0m[0;34m,[0m [0;34m**[0m[0mkwargs[0m[0;34m)[0m[0;34m[0m[0;34m[0m[0m
[0m[1;32m    656[0m [0;34m[0m[0m
[1;32m    657[0m         [0;31m# Total elapsed time of the request (approximately)[0m[0;34m[0m[0;34m[0m[0m

[0;32m/usr/local/lib/python3.9/site-packages/requests/adapters.py[0m in [0;36msend[0;34m(self, request, stream, timeout, verify, cert, proxies)[0m
[1;32m    514[0m                 [0;32mraise[0m [0mSSLError[0m[0;34m([0m[0me[0m[0;34m,[0m [0mrequest[0m[0;34m=[0m[0mrequest[0m[0;34m)[0m[0;34m[0m[0;34m[0m[0m
[1;32m    515[0m [0;34m[0m[0m
[0;32m--> 516[0;31m             [0;32mraise[0m [0mConnectionError[0m[0;34m([0m[0me[0m[0;34m,[0m [0mrequest[0m[0;34m=[0m[0mrequest[0m[0;34m)[0m[0;34m[0m[0;34m[0m[0m
[0m[1;32m    517[0m [0;34m[0m[0m
[1;32m    518[0m         [0;32mexcept[0m [0mClosedPoolError[0m [0;32mas[0m [0me[0m[0;34m:[0m[0;34m[0m[0;34m[0m[0m

[0;31mConnectionError[0m: HTTPConnectionPool(host='localhost', port=3000): Max retries exceeded with url: / (Caused by NewConnectionError('<urllib3.connection.HTTPConnection object at 0x12438b070>: Failed to establish a new connection: [Errno 61] Connection refused'))
ConnectionError: HTTPConnectionPool(host='localhost', port=3000): Max retries exceeded with url: / (Caused by NewConnectionError('<urllib3.connection.HTTPConnection object at 0x12438b070>: Failed to establish a new connection: [Errno 61] Connection refused'))

